Workbook

Sheet Как пользоваться
A1: Постатейный факторный анализ корректировки бюджета
A2: Расчетное приложение к методике. Валюта — российский рубль, суммы без НДС.
A4: 1. Базовый бюджет — редакция, утвержденная на старте финансирования. Промежуточные версии его не заменяют.
A5: 2. Сначала выведите за периметр новые очереди и выбывшие объекты. В факторы они не входят.
A6: 3. Заполняйте только желтые ячейки строк нижнего уровня на листе «Шаблон». Агрегаты и итог считаются сами.
A7: 4. Колонка «Контроль» обязана быть нулевой по каждой строке. Ненулевой остаток — не четвертый фактор, а незавершенный расчет.
A8: 5. Инфляция считается на исходный объем и исходное решение относительно дефляторов, утвержденных в базовой модели.
A9: 6. Изменения проектной документации оцениваются в текущих ценах. Инфляция приростного объема повторно в фактор 1 не ставится.
A10: 7. Страхование и процент генподряда считаются после разложения своей базы. Проценты по кредиту в бюджет проекта не входят и в факторы не ставятся. Калькулятор процента генподряда — на листе «Производные затраты».
A11: 8. Одну позицию удобно разложить на листе «Калькулятор позиции». Индекс собирается на листе «Индекс».
A12: 9. Риск до ввода — это риск нового роста сверх откорректированного бюджета. Качественная оценка стоит в колонке «Риск до ввода», величина в рублях — в колонке «Сумма риска». В тождество факторов сумма риска не входит.
A13: 10. Лист «Условный пример» — постатейная таблица. Под ней упрощенные формулы сумм факторов. Лист «Укрупненный анализ» сводит те же цифры в пять групп. Это не заключение по реальному объекту.
... A17: Листы файла
A18: Лист | B18: Назначение
A19: Как пользоваться | B19: Порядок ввода и контроль
A20: Классификатор | B20: Коды статей, которые нельзя схлопывать и нельзя заводить вручную на агрегатах
A21: Шаблон | B21: Пустая постатейная таблица с формулами
A22: Условный пример | B22: Постатейный пример без процентов по кредиту: 7,02 млрд руб. → 8,175 млрд руб.
A23: Укрупненный анализ | B23: Пять групп: СМР, ПИР, наружные сети и ТУ, коммерческие, административные
A24: Калькулятор позиции | B24: Формула трех факторов для одной работы
A25: Ориентировочный бюджет | B25: Удельная ставка до рабочей документации: инфляция, отступление от паспорта и уточнение
A26: Индекс | B26: Сборка коэффициента инфляции из весов ресурсов
A27: Производные затраты | B27: Процент генподряда и содержание команды. Процентов по кредиту на листе нет
A28: Риск | B28: Шкала баллов до ввода в эксплуатацию
A29: Реестр документов | B29: Минимальный комплект доказательств по факторам
A30: Контроль | B30: Сверка итога условного примера

Sheet Классификатор
A1: Классификатор статей бюджета
A2: Нулевая строка не удаляется. Строка 03.04 заполняется только при наличии технологического оборудования в периметре бюджета.
A4: Код | B4: Наименование | C4: Уровень | D4: Примечание по отнесению | E4: Типовой носитель фактора
A5: 01 | B5: Подготовка строительства и земля | C5: 1 | D5: Вне периметра остается покупка прав на участок, если ее не было в бюджете T0. | E5: Смешанный
A6: 01.01 | B6: Градостроительная подготовка и права на земельный участок | C6: 2 | D6: Градостроительные платежи редко имеют строительный дефлятор. | E6: Смешанный
A7: 01.02 | B7: Освобождение территории, снос и перенос существующих сетей | C7: 2 | D7: Объем подтверждается исполнительными схемами, а не только счетами. | E7: Смешанный
A8: 01.03 | B8: Земляные работы, котлован, крепление и водопонижение | C8: 2 | D8: Смена конструкции крепления из-за геологии — фактор ПСД. Фактический водоприток при тех же чертежах — иная причина. | E8: Смешанный
A9: 01.04 | B9: Временная строительная инфраструктура площадки | C9: 2 | D9: Городок заказчика не дублируется внутри договоров подрядчиков. | E9: Смешанный
A10: 02 | B10: Проектно-изыскательские работы и авторский надзор | C10: 1 | D10: Индекс СМР к проектированию не применяется. | E10: Ставки проектирования и состав разделов
A11: 02.01 | B11: Инженерные изыскания | C11: 2 | D11: Допизыскания под новое решение — фактор ПСД. | E11: Ставки проектирования и состав разделов
A12: 02.02 | B12: Проектная документация | C12: 2 | D12: Сверяются два задания на проектирование. | E12: Ставки проектирования и состав разделов
A13: 02.03 | B13: Рабочая документация | C13: 2 | D13: Главное доказательство — реестр измов с причиной. | E13: Ставки проектирования и состав разделов
A14: 02.04 | B14: Экспертиза проектной документации и результатов изысканий | C14: 2 | D14: Повторная экспертиза из-за смены ТЭП — фактор ПСД. | E14: Ставки проектирования и состав разделов
A15: 02.05 | B15: Авторский надзор | C15: 2 | D15: Месяцы сверх даты ввода T0 не смешиваются с содержанием службы заказчика. | E15: Ставки проектирования и состав разделов
A16: 03 | B16: Строительно-монтажные работы | C16: 1 | D16: Модель контрактования определяется по договору строки, а не одним ярлыком на проект. | E16: Объем, расценка, индекс ресурсов
... A49: 06.03 | B49: Комиссии, гарантии, обязательные платежи и консультации | C49: 2 | D49: В том числе земельные платежи периода строительства и эффект ставки НДС, если он не вынесен справочно. | E49: Тариф страхования, регистр резерва, срок гарантий

Sheet Шаблон
A1: Шаблон постатейного факторного анализа
A2: Единица измерения — рубль без НДС. Желтым отмечен ввод. Отклонение, процент, агрегаты и колонка «Контроль» считаются формулами. Контроль = инфляция + изменения ПСД + иные причины − отклонение и должен быть равен нулю. Сумма риска — оценка возможного нового удорожания сверх откорректированного бюджета. В контроль факторов она не входит. Агрегаты не вводятся вручную: они суммируют строки, которые стоят ниже до следующего агрегата того же или более высокого уровня.
A4: Код | B4: Наименование статьи | C4: Базовый бюджет, руб. | D4: Откорректированный бюджет, руб. | E4: Отклонение, руб. | F4: Отклонение, % | G4: Фактор 1. Инфляция, руб. | H4: Фактор 2. Изменения ПСД, руб. | I4: Фактор 3. Иные причины, руб. | J4: Контроль, руб. | K4: Причины изменения | L4: Риск до ввода | M4: Сумма риска, руб. | N4: Комментарий к риску | O4: Класс надежности
A5: 01 | B5: Подготовка строительства и земля | C5: =SUM(C6,C7,C8,C9) | D5: =SUM(D6,D7,D8,D9) | E5: =D5-C5 | F5: =IF(AND(C5=0,D5=0),"—",IF(C5=0,"новая статья",E5/C5)) | G5: =SUM(G6,G7,G8,G9) | H5: =SUM(H6,H7,H8,H9) | I5: =SUM(I6,I7,I8,I9) | J5: =G5+H5+I5-E5 | M5: =SUM(M6,M7,M8,M9)
A6: 01.01 | B6: Градостроительная подготовка и права на земельный участок | E6: =D6-C6 | F6: =IF(AND(C6=0,D6=0),"—",IF(C6=0,"новая статья",E6/C6)) | J6: =G6+H6+I6-E6
A7: 01.02 | B7: Освобождение территории, снос и перенос существующих сетей | E7: =D7-C7 | F7: =IF(AND(C7=0,D7=0),"—",IF(C7=0,"новая статья",E7/C7)) | J7: =G7+H7+I7-E7
A8: 01.03 | B8: Земляные работы, котлован, крепление и водопонижение | E8: =D8-C8 | F8: =IF(AND(C8=0,D8=0),"—",IF(C8=0,"новая статья",E8/C8)) | J8: =G8+H8+I8-E8
A9: 01.04 | B9: Временная строительная инфраструктура площадки | E9: =D9-C9 | F9: =IF(AND(C9=0,D9=0),"—",IF(C9=0,"новая статья",E9/C9)) | J9: =G9+H9+I9-E9
A10: 02 | B10: Проектно-изыскательские работы и авторский надзор | C10: =SUM(C11,C12,C13,C14,C15) | D10: =SUM(D11,D12,D13,D14,D15) | E10: =D10-C10 | F10: =IF(AND(C10=0,D10=0),"—",IF(C10=0,"новая статья",E10/C10)) | G10: =SUM(G11,G12,G13,G14,G15) | H10: =SUM(H11,H12,H13,H14,H15) | I10: =SUM(I11,I12,I13,I14,I15) | J10: =G10+H10+I10-E10 | M10: =SUM(M11,M12,M13,M14,M15)
A11: 02.01 | B11: Инженерные изыскания | E11: =D11-C11 | F11: =IF(AND(C11=0,D11=0),"—",IF(C11=0,"новая статья",E11/C11)) | J11: =G11+H11+I11-E11
A12: 02.02 | B12: Проектная документация | E12: =D12-C12 | F12: =IF(AND(C12=0,D12=0),"—",IF(C12=0,"новая статья",E12/C12)) | J12: =G12+H12+I12-E12
A13: 02.03 | B13: Рабочая документация | E13: =D13-C13 | F13: =IF(AND(C13=0,D13=0),"—",IF(C13=0,"новая статья",E13/C13)) | J13: =G13+H13+I13-E13
A14: 02.04 | B14: Экспертиза проектной документации и результатов изысканий | E14: =D14-C14 | F14: =IF(AND(C14=0,D14=0),"—",IF(C14=0,"новая статья",E14/C14)) | J14: =G14+H14+I14-E14
A15: 02.05 | B15: Авторский надзор | E15: =D15-C15 | F15: =IF(AND(C15=0,D15=0),"—",IF(C15=0,"новая статья",E15/C15)) | J15: =G15+H15+I15-E15
A16: 03 | B16: Строительно-монтажные работы | C16: =SUM(C17,C25,C31,C37) | D16: =SUM(D17,D25,D31,D37) | E16: =D16-C16 | F16: =IF(AND(C16=0,D16=0),"—",IF(C16=0,"новая статья",E16/C16)) | G16: =SUM(G17,G25,G31,G37) | H16: =SUM(H17,H25,H31,H37) | I16: =SUM(I17,I25,I31,I37) | J16: =G16+H16+I16-E16 | M16: =SUM(M17,M25,M31,M37)
A17: 03.01 | B17: Общестроительные работы и конструктив | C17: =SUM(C18,C19,C20,C21,C22,C23,C24) | D17: =SUM(D18,D19,D20,D21,D22,D23,D24) | E17: =D17-C17 | F17: =IF(AND(C17=0,D17=0),"—",IF(C17=0,"новая статья",E17/C17)) | G17: =SUM(G18,G19,G20,G21,G22,G23,G24) | H17: =SUM(H18,H19,H20,H21,H22,H23,H24) | I17: =SUM(I18,I19,I20,I21,I22,I23,I24) | J17: =G17+H17+I17-E17 | M17: =SUM(M18,M19,M20,M21,M22,M23,M24)
A18: 03.01.01 | B18: Фундаменты и подземная часть | E18: =D18-C18 | F18: =IF(AND(C18=0,D18=0),"—",IF(C18=0,"новая статья",E18/C18)) | J18: =G18+H18+I18-E18
A19: 03.01.02 | B19: Несущий каркас | E19: =D19-C19 | F19: =IF(AND(C19=0,D19=0),"—",IF(C19=0,"новая статья",E19/C19)) | J19: =G19+H19+I19-E19
A20: 03.01.03 | B20: Стены и перегородки | E20: =D20-C20 | F20: =IF(AND(C20=0,D20=0),"—",IF(C20=0,"новая статья",E20/C20)) | J20: =G20+H20+I20-E20
A21: 03.01.04 | B21: Фасады и кровля | E21: =D21-C21 | F21: =IF(AND(C21=0,D21=0),"—",IF(C21=0,"новая статья",E21/C21)) | J21: =G21+H21+I21-E21
A22: 03.01.05 | B22: Окна, двери и светопрозрачные конструкции | E22: =D22-C22 | F22: =IF(AND(C22=0,D22=0),"—",IF(C22=0,"новая статья",E22/C22)) | J22: =G22+H22+I22-E22
A23: 03.01.06 | B23: Внутренняя черновая отделка | E23: =D23-C23 | F23: =IF(AND(C23=0,D23=0),"—",IF(C23=0,"новая статья",E23/C23)) | J23: =G23+H23+I23-E23
A24: 03.01.07 | B24: Лифты и подъемное оборудование | E24: =D24-C24 | F24: =IF(AND(C24=0,D24=0),"—",IF(C24=0,"новая статья",E24/C24)) | J24: =G24+H24+I24-E24
A25: 03.02 | B25: Внутренние инженерные системы | C25: =SUM(C26,C27,C28,C29,C30) | D25: =SUM(D26,D27,D28,D29,D30) | E25: =D25-C25 | F25: =IF(AND(C25=0,D25=0),"—",IF(C25=0,"новая статья",E25/C25)) | G25: =SUM(G26,G27,G28,G29,G30) | H25: =SUM(H26,H27,H28,H29,H30) | I25: =SUM(I26,I27,I28,I29,I30) | J25: =G25+H25+I25-E25 | M25: =SUM(M26,M27,M28,M29,M30)
A26: 03.02.01 | B26: Отопление, вентиляция и кондиционирование | E26: =D26-C26 | F26: =IF(AND(C26=0,D26=0),"—",IF(C26=0,"новая статья",E26/C26)) | J26: =G26+H26+I26-E26
A27: 03.02.02 | B27: Водоснабжение и водоотведение | E27: =D27-C27 | F27: =IF(AND(C27=0,D27=0),"—",IF(C27=0,"новая статья",E27/C27)) | J27: =G27+H27+I27-E27
A28: 03.02.03 | B28: Электрооборудование, электроосвещение и молниезащита | E28: =D28-C28 | F28: =IF(AND(C28=0,D28=0),"—",IF(C28=0,"новая статья",E28/C28)) | J28: =G28+H28+I28-E28
A29: 03.02.04 | B29: Сети связи, АПС, СОУЭ, СКУД, автоматизация и диспетчеризация | E29: =D29-C29 | F29: =IF(AND(C29=0,D29=0),"—",IF(C29=0,"новая статья",E29/C29)) | J29: =G29+H29+I29-E29
A30: 03.02.05 | B30: Системы противопожарной защиты и прочие внутренние системы | E30: =D30-C30 | F30: =IF(AND(C30=0,D30=0),"—",IF(C30=0,"новая статья",E30/C30)) | J30: =G30+H30+I30-E30
A31: 03.03 | B31: Наружные инженерные сети и благоустройство | C31: =SUM(C32,C33,C34,C35,C36) | D31: =SUM(D32,D33,D34,D35,D36) | E31: =D31-C31 | F31: =IF(AND(C31=0,D31=0),"—",IF(C31=0,"новая статья",E31/C31)) | G31: =SUM(G32,G33,G34,G35,G36) | H31: =SUM(H32,H33,H34,H35,H36) | I31: =SUM(I32,I33,I34,I35,I36) | J31: =G31+H31+I31-E31 | M31: =SUM(M32,M33,M34,M35,M36)
A32: 03.03.01 | B32: Наружные сети водоснабжения, водоотведения и ливневой канализации | E32: =D32-C32 | F32: =IF(AND(C32=0,D32=0),"—",IF(C32=0,"новая статья",E32/C32)) | J32: =G32+H32+I32-E32
A33: 03.03.02 | B33: Наружные сети теплоснабжения | E33: =D33-C33 | F33: =IF(AND(C33=0,D33=0),"—",IF(C33=0,"новая статья",E33/C33)) | J33: =G33+H33+I33-E33
A34: 03.03.03 | B34: Наружное электроснабжение и трансформаторные подстанции | E34: =D34-C34 | F34: =IF(AND(C34=0,D34=0),"—",IF(C34=0,"новая статья",E34/C34)) | J34: =G34+H34+I34-E34
A35: 03.03.04 | B35: Наружные сети связи | E35: =D35-C35 | F35: =IF(AND(C35=0,D35=0),"—",IF(C35=0,"новая статья",E35/C35)) | J35: =G35+H35+I35-E35
A36: 03.03.05 | B36: Дороги, благоустройство и малые архитектурные формы | E36: =D36-C36 | F36: =IF(AND(C36=0,D36=0),"—",IF(C36=0,"новая статья",E36/C36)) | J36: =G36+H36+I36-E36
A37: 03.04 | B37: Технологическое оборудование и пусконаладка | E37: =D37-C37 | F37: =IF(AND(C37=0,D37=0),"—",IF(C37=0,"новая статья",E37/C37)) | J37: =G37+H37+I37-E37
A38: 04 | B38: Затраты на управление проектом | C38: =SUM(C39,C40,C41) | D38: =SUM(D39,D40,D41) | E38: =D38-C38 | F38: =IF(AND(C38=0,D38=0),"—",IF(C38=0,"новая статья",E38/C38)) | G38: =SUM(G39,G40,G41) | H38: =SUM(H39,H40,H41) | I38: =SUM(I39,I40,I41) | J38: =G38+H38+I38-E38 | M38: =SUM(M39,M40,M41)
A39: 04.01 | B39: Служба заказчика и технический заказчик | E39: =D39-C39 | F39: =IF(AND(C39=0,D39=0),"—",IF(C39=0,"новая статья",E39/C39)) | J39: =G39+H39+I39-E39
A40: 04.02 | B40: Вознаграждение генподрядчика либо управляющего строительством | E40: =D40-C40 | F40: =IF(AND(C40=0,D40=0),"—",IF(C40=0,"новая статья",E40/C40)) | J40: =G40+H40+I40-E40
A41: 04.03 | B41: Строительный контроль, охрана труда, качество и охрана площадки | E41: =D41-C41 | F41: =IF(AND(C41=0,D41=0),"—",IF(C41=0,"новая статья",E41/C41)) | J41: =G41+H41+I41-E41
...

Sheet Условный пример
A1: Условный пример постатейного факторного анализа
A2: Единица измерения — рубль без НДС. Желтым отмечен ввод. Отклонение, процент, агрегаты и колонка «Контроль» считаются формулами. Контроль = инфляция + изменения ПСД + иные причины − отклонение и должен быть равен нулю. Сумма риска — оценка возможного нового удорожания сверх откорректированного бюджета. В контроль факторов она не входит. Цифры примера условные. Проценты по кредиту в бюджет не включены.
A4: Код | B4: Наименование статьи | C4: Базовый бюджет, руб. | D4: Откорректированный бюджет, руб. | E4: Отклонение, руб. | F4: Отклонение, % | G4: Фактор 1. Инфляция, руб. | H4: Фактор 2. Изменения ПСД, руб. | I4: Фактор 3. Иные причины, руб. | J4: Контроль, руб. | K4: Причины изменения | L4: Риск до ввода | M4: Сумма риска, руб. | N4: Комментарий к риску | O4: Класс надежности
A5: 01 | B5: Подготовка строительства и земля | C5: =SUM(C6,C7,C8,C9) | D5: =SUM(D6,D7,D8,D9) | E5: =D5-C5 | F5: =IF(AND(C5=0,D5=0),"—",IF(C5=0,"новая статья",E5/C5)) | G5: =SUM(G6,G7,G8,G9) | H5: =SUM(H6,H7,H8,H9) | I5: =SUM(I6,I7,I8,I9) | J5: =G5+H5+I5-E5 | K5: Свертка вложенных строк. | L5: Средний | M5: =SUM(M6,M7,M8,M9) | N5: Оценка агрегата — наихудшая существенная вложенная строка.
A6: 01.01 | B6: Градостроительная подготовка и права на земельный участок | C6: 40000000 | D6: 42000000 | E6: =D6-C6 | F6: =IF(AND(C6=0,D6=0),"—",IF(C6=0,"новая статья",E6/C6)) | G6: 1000000 | H6: 0 | I6: 1000000 | J6: =G6+H6+I6-E6 | K6: Плата за изменение документации планировки и актуализацию ГПЗУ сверх исходного допуска. Строительный дефлятор к этим платежам почти не применяется. | L6: Низкий | M6: 0 | N6: Градостроительная подготовка завершена, открытых предписаний нет. | O6: Б
A7: 01.02 | B7: Освобождение территории, снос и перенос существующих сетей | C7: 90000000 | D7: 115000000 | E7: =D7-C7 | F7: =IF(AND(C7=0,D7=0),"—",IF(C7=0,"новая статья",E7/C7)) | G7: 8000000 | H7: 14000000 | I7: 3000000 | J7: =G7+H7+I7-E7 | K7: Дополнительные объемы переноса теплосети и сноса по уточненным обмерам и новым техническим условиям. Индекс на демонтаж и перевозку выше дефлятора T0. Обременения сверх объемов ПСД отнесены к иным причинам. | L7: Средний | M7: 8000000 | N7: Часть переносов не законтрактована. Возможен новый объем по требованиям смежных собственников. | O7: А
A8: 01.03 | B8: Земляные работы, котлован, крепление и водопонижение | C8: 140000000 | D8: 165000000 | E8: =D8-C8 | F8: =IF(AND(C8=0,D8=0),"—",IF(C8=0,"новая статья",E8/C8)) | G8: 12000000 | H8: 10000000 | I8: 3000000 | J8: =G8+H8+I8-E8 | K8: Рост объема вывоза и крепления после корректировки геологии и отметки фундамента. Индекс топлива, транспорта и оплаты труда машинистов выше плана. Водопонижение сверх проекта из-за фактического водопритока отнесено к иным причинам. | L8: Средний | M8: 10000000 | N8: Котлован выполнен частично. Остается риск водопритока и зимнего удорожания незакрытого остатка. | O8: А
A9: 01.04 | B9: Временная строительная инфраструктура площадки | C9: 50000000 | D9: 58000000 | E9: =D9-C9 | F9: =IF(AND(C9=0,D9=0),"—",IF(C9=0,"новая статья",E9/C9)) | G9: 4000000 | H9: 4000000 | I9: 0 | J9: =G9+H9+I9-E9 | K9: Удорожание временных сетей и городка в пределах индекса оплаты труда и материалов плюс расширение городка под дополнительную сменность, вызванную ростом объемов. | L9: Низкий | M9: 0 | N9: Затраты в основном уже понесены. | O9: Б
A10: 02 | B10: Проектно-изыскательские работы и авторский надзор | C10: =SUM(C11,C12,C13,C14,C15) | D10: =SUM(D11,D12,D13,D14,D15) | E10: =D10-C10 | F10: =IF(AND(C10=0,D10=0),"—",IF(C10=0,"новая статья",E10/C10)) | G10: =SUM(G11,G12,G13,G14,G15) | H10: =SUM(H11,H12,H13,H14,H15) | I10: =SUM(I11,I12,I13,I14,I15) | J10: =G10+H10+I10-E10 | K10: Свертка вложенных строк. | L10: Средний | M10: =SUM(M11,M12,M13,M14,M15) | N10: Оценка агрегата — наихудшая существенная вложенная строка.
A11: 02.01 | B11: Инженерные изыскания | C11: 35000000 | D11: 40000000 | E11: =D11-C11 | F11: =IF(AND(C11=0,D11=0),"—",IF(C11=0,"новая статья",E11/C11)) | G11: 2000000 | H11: 3000000 | I11: 0 | J11: =G11+H11+I11-E11 | K11: Дополнительные геотехнические и экологические изыскания под измененные конструктивные решения. Отдельно учтен индекс договорных цен изыскателей к дефлятору T0. | L11: Низкий | M11: 0 | N11: Полевые работы закрыты актами. | O11: А
A12: 02.02 | B12: Проектная документация | C12: 90000000 | D12: 100000000 | E12: =D12-C12 | F12: =IF(AND(C12=0,D12=0),"—",IF(C12=0,"новая статья",E12/C12)) | G12: 5000000 | H12: 4000000 | I12: 1000000 | J12: =G12+H12+I12-E12 | K12: Корректировка стадии П под новые ТЭП. Индексация частично выполненных этапов. Доплата за сжатый срок выпуска, не вытекающая из состава документации, отнесена к иным причинам. | L12: Низкий | M12: 0 | N12: Экспертиза стадии П пройдена. | O12: А
A13: 02.03 | B13: Рабочая документация | C13: 110000000 | D13: 145000000 | E13: =D13-C13 | F13: =IF(AND(C13=0,D13=0),"—",IF(C13=0,"новая статья",E13/C13)) | G13: 8000000 | H13: 22000000 | I13: 5000000 | J13: =G13+H13+I13-E13 | K13: Основной прирост — дополнительные комплекты рабочей документации по измененным разделам КР, АР и инженерных систем. Индекс ставок проектировщиков учтен отдельно. Счета за переделки исходных коллизий при неизменных решениях отнесены к иным причинам. | L13: Средний | M13: 12000000 | N13: Комплект рабочей документации не завершен. До окончания СМР вероятны дополнительные измы. | O13: А
A14: 02.04 | B14: Экспертиза проектной документации и результатов изысканий | C14: 25000000 | D14: 30000000 | E14: =D14-C14 | F14: =IF(AND(C14=0,D14=0),"—",IF(C14=0,"новая статья",E14/C14)) | G14: 1000000 | H14: 3000000 | I14: 1000000 | J14: =G14+H14+I14-E14 | K14: Повторная экспертиза в связи с изменением ТЭП. Тарифный индекс на исходный состав. Сопутствующие расходы на устранение замечаний без смены решений отнесены к иным причинам. | L14: Низкий | M14: 0 | N14: Повторное заключение получено. | O14: А
A15: 02.05 | B15: Авторский надзор | C15: 20000000 | D15: 25000000 | E15: =D15-C15 | F15: =IF(AND(C15=0,D15=0),"—",IF(C15=0,"новая статья",E15/C15)) | G15: 2000000 | H15: 3000000 | I15: 0 | J15: =G15+H15+I15-E15 | K15: Индексация помесячной ставки на исходный срок и дополнительные выезды по новым разделам рабочей документации. Чистое удлинение срока стройки в эту строку не включено, чтобы не задвоить его с группой 04. | L15: Средний | M15: 4000000 | N15: При следующем сдвиге ввода вероятно дополнительное соглашение. В бюджете T1 его еще нет. | O15: А
A16: 03 | B16: Строительно-монтажные работы | C16: =SUM(C17,C25,C31,C37) | D16: =SUM(D17,D25,D31,D37) | E16: =D16-C16 | F16: =IF(AND(C16=0,D16=0),"—",IF(C16=0,"новая статья",E16/C16)) | G16: =SUM(G17,G25,G31,G37) | H16: =SUM(H17,H25,H31,H37) | I16: =SUM(I17,I25,I31,I37) | J16: =G16+H16+I16-E16 | K16: Свертка вложенных строк. | L16: Высокий | M16: =SUM(M17,M25,M31,M37) | N16: Оценка агрегата — наихудшая существенная вложенная строка.
A17: 03.01 | B17: Общестроительные работы и конструктив | C17: =SUM(C18,C19,C20,C21,C22,C23,C24) | D17: =SUM(D18,D19,D20,D21,D22,D23,D24) | E17: =D17-C17 | F17: =IF(AND(C17=0,D17=0),"—",IF(C17=0,"новая статья",E17/C17)) | G17: =SUM(G18,G19,G20,G21,G22,G23,G24) | H17: =SUM(H18,H19,H20,H21,H22,H23,H24) | I17: =SUM(I18,I19,I20,I21,I22,I23,I24) | J17: =G17+H17+I17-E17 | K17: Свертка вложенных строк. | L17: Высокий | M17: =SUM(M18,M19,M20,M21,M22,M23,M24) | N17: Оценка агрегата — наихудшая существенная вложенная строка.
A18: 03.01.01 | B18: Фундаменты и подземная часть | C18: 620000000 | D18: 740000000 | E18: =D18-C18 | F18: =IF(AND(C18=0,D18=0),"—",IF(C18=0,"новая статья",E18/C18)) | G18: 55000000 | H18: 55000000 | I18: 10000000 | J18: =G18+H18+I18-E18 | K18: Увеличение объемов плиты и свай после изменения геологии и нагрузок. Индекс бетона, арматуры и оплаты труда на исходный объем. Сверхиндексная цена субподрядчика на сваи отнесена к иным причинам. | L18: Средний | M18: 20000000 | N18: Подземная часть законтрактована по единичным расценкам примерно на 70%. Остаток зависит от исполнительной геологии. | O18: А
A19: 03.01.02 | B19: Несущий каркас | C19: 980000000 | D19: 1120000000 | E19: =D19-C19 | F19: =IF(AND(C19=0,D19=0),"—",IF(C19=0,"новая статья",E19/C19)) | G19: 90000000 | H19: 40000000 | I19: 10000000 | J19: =G19+H19+I19-E19 | K19: Индекс арматуры, бетона, опалубки и оплаты труда на исходный объем каркаса. Прирост расхода арматуры по новой рабочей документации. Часть расценок выше индексированной цены исходного решения. | L19: Средний | M19: 25000000 | N19: Расценки зафиксированы до текущей отметки. Верхние этажи еще открыты. | O19: А
A20: 03.01.03 | B20: Стены и перегородки | C20: 310000000 | D20: 350000000 | E20: =D20-C20 | F20: =IF(AND(C20=0,D20=0),"—",IF(C20=0,"новая статья",E20/C20)) | G20: 28000000 | H20: 12000000 | I20: 0 | J20: =G20+H20+I20-E20 | K20: Индекс кладки и перегородок на исходный объем. Дополнительные перегородки по корректировке планировок. Отклонения цены от индекса нет. | L20: Низкий | M20: 0 | N20: Решения типовые, расценки законтрактованы. | O20: А
A21: 03.01.04 | B21: Фасады и кровля | C21: 540000000 | D21: 650000000 | E21: =D21-C21 | F21: =IF(AND(C21=0,D21=0),"—",IF(C21=0,"новая статья",E21/C21)) | G21: 48000000 | H21: 55000000 | I21: 7000000 | J21: =G21+H21+I21-E21 | K21: Замена штукатурного фасада на навесной вентилируемый и рост площади кровли оценены по рыночной цене нового решения. Индекс металла и утеплителя на исходное решение учтен отдельно. Логистическая надбавка поставщика сверх рынка отнесена к иным причинам. | L21: Высокий | M21: 45000000 | N21: Фасадный договор не подписан, узлы рабочей документации не утверждены, валютная составляющая фурнитуры открыта. | O21: Б
A22: 03.01.05 | B22: Окна, двери и светопрозрачные конструкции | C22: 280000000 | D22: 320000000 | E22: =D22-C22 | F22: =IF(AND(C22=0,D22=0),"—",IF(C22=0,"новая статья",E22/C22)) | G22: 25000000 | H22: 12000000 | I22: 3000000 | J22: =G22+H22+I22-E22 | K22: Индекс профилей и стеклопакетов на исходную спецификацию. Увеличение площади витражей по архитектурным решениям. Доплата за срочное изготовление части позиций отнесена к иным причинам. | L22: Средний | M22: 15000000 | N22: Спецификация согласована не полностью. Металл и стекло верхних этажей не закуплены. | O22: А
A23: 03.01.06 | B23: Внутренняя черновая отделка | C23: 220000000 | D23: 250000000 | E23: =D23-C23 | F23: =IF(AND(C23=0,D23=0),"—",IF(C23=0,"новая статья",E23/C23)) | G23: 20000000 | H23: 10000000 | I23: 0 | J23: =G23+H23+I23-E23 | K23: Индекс сухих смесей и оплаты труда. Дополнительные площади подготовки стен после смены типа фасада. Сверхиндексного отклонения цены нет. | L23: Средний | M23: 12000000 | N23: Отделка не законтрактована, объемы зависят от финальной рабочей документации. | O23: Б
A24: 03.01.07 | B24: Лифты и подъемное оборудование | C24: 150000000 | D24: 170000000 | E24: =D24-C24 | F24: =IF(AND(C24=0,D24=0),"—",IF(C24=0,"новая статья",E24/C24)) | G24: 14000000 | H24: 6000000 | I24: 0 | J24: =G24+H24+I24-E24 | K24: Индекс оборудования на исходную спецификацию. Добавление подъема и изменение грузоподъемности по новой планировке. Контрактная цена не превышает рыночный аналог. | L24: Средний | M24: 10000000 | N24: Договор поставки не заключен. Срок изготовления лежит на критическом пути ввода. | O24: Б
A25: 03.02 | B25: Внутренние инженерные системы | C25: =SUM(C26,C27,C28,C29,C30) | D25: =SUM(D26,D27,D28,D29,D30) | E25: =D25-C25 | F25: =IF(AND(C25=0,D25=0),"—",IF(C25=0,"новая статья",E25/C25)) | G25: =SUM(G26,G27,G28,G29,G30) | H25: =SUM(H26,H27,H28,H29,H30) | I25: =SUM(I26,I27,I28,I29,I30) | J25: =G25+H25+I25-E25 | K25: Свертка вложенных строк. | L25: Высокий | M25: =SUM(M26,M27,M28,M29,M30) | N25: Оценка агрегата — наихудшая существенная вложенная строка.
A26: 03.02.01 | B26: Отопление, вентиляция и кондиционирование | C26: 380000000 | D26: 450000000 | E26: =D26-C26 | F26: =IF(AND(C26=0,D26=0),"—",IF(C26=0,"новая статья",E26/C26)) | G26: 30000000 | H26: 35000000 | I26: 5000000 | J26: =G26+H26+I26-E26 | K26: Индекс исходного состава оборудования относительно дефлятора и курсового допущения T0. Новая производительность и переразводка по измененным планировкам оценены по текущим рыночным аналогам. Превышение цены выбранного поставщика над аналогом отнесено к иным причинам. | L26: Высокий | M26: 40000000 | N26: Рабочая документация выпущена частично. Основное оборудование не законтрактовано. | O26: Б
A27: 03.02.02 | B27: Водоснабжение и водоотведение | C27: 260000000 | D27: 290000000 | E27: =D27-C27 | F27: =IF(AND(C27=0,D27=0),"—",IF(C27=0,"новая статья",E27/C27)) | G27: 22000000 | H27: 8000000 | I27: 0 | J27: =G27+H27+I27-E27 | K27: Индекс труб, арматуры и сантехнических приборов на исходную систему. Дополнительные санузлы и стояки по новым планировкам. Цена в бюджете равна индексированной рыночной цене. | L27: Средний | M27: 8000000 | N27: Система в основном типовая, но спецификация приборов не закрыта полностью. | O27: А
A28: 03.02.03 | B28: Электрооборудование, электроосвещение и молниезащита | C28: 420000000 | D28: 490000000 | E28: =D28-C28 | F28: =IF(AND(C28=0,D28=0),"—",IF(C28=0,"новая статья",E28/C28)) | G28: 35000000 | H28: 30000000 | I28: 5000000 | J28: =G28+H28+I28-E28 | K28: Индекс кабеля и щитового оборудования на исходную нагрузку. Рост установленной мощности и замена сечений по новой рабочей документации. Надбавка за срочную поставку отнесена к иным причинам. | L28: Высокий | M28: 35000000 | N28: Нагрузка не подтверждена окончательными техническими условиями. Спецификация щитов открыта. | O28: Б
A29: 03.02.04 | B29: Сети связи, АПС, СОУЭ, СКУД, автоматизация и диспетчеризация | C29: 210000000 | D29: 250000000 | E29: =D29-C29 | F29: =IF(AND(C29=0,D29=0),"—",IF(C29=0,"новая статья",E29/C29)) | G29: 15000000 | H29: 20000000 | I29: 5000000 | J29: =G29+H29+I29-E29 | K29: Расширение состава систем относительно исходного задания на проектирование. Индекс на исходный комплект. Надбавка вендора сверх двух независимых аналогов отнесена к иным причинам. | L29: Высокий | M29: 25000000 | N29: Задание на слаботочные системы пересматривается. Договоры не заключены. | O29: В
A30: 03.02.05 | B30: Системы противопожарной защиты и прочие внутренние системы | C30: 130000000 | D30: 140000000 | E30: =D30-C30 | F30: =IF(AND(C30=0,D30=0),"—",IF(C30=0,"новая статья",E30/C30)) | G30: 8000000 | H30: 2000000 | I30: 0 | J30: =G30+H30+I30-E30 | K30: Индекс на исходные системы. Локальное расширение зон покрытия по новой планировке. | L30: Средний | M30: 6000000 | N30: Состав зависит от финальной редакции пожарного раздела. | O30: Б
A31: 03.03 | B31: Наружные инженерные сети и благоустройство | C31: =SUM(C32,C33,C34,C35,C36) | D31: =SUM(D32,D33,D34,D35,D36) | E31: =D31-C31 | F31: =IF(AND(C31=0,D31=0),"—",IF(C31=0,"новая статья",E31/C31)) | G31: =SUM(G32,G33,G34,G35,G36) | H31: =SUM(H32,H33,H34,H35,H36) | I31: =SUM(I32,I33,I34,I35,I36) | J31: =G31+H31+I31-E31 | K31: Свертка вложенных строк. | L31: Высокий | M31: =SUM(M32,M33,M34,M35,M36) | N31: Оценка агрегата — наихудшая существенная вложенная строка.
A32: 03.03.01 | B32: Наружные сети водоснабжения, водоотведения и ливневой канализации | C32: 180000000 | D32: 210000000 | E32: =D32-C32 | F32: =IF(AND(C32=0,D32=0),"—",IF(C32=0,"новая статья",E32/C32)) | G32: 15000000 | H32: 12000000 | I32: 3000000 | J32: =G32+H32+I32-E32 | K32: Индекс земляных работ и труб на исходную трассу. Удлинение трасс по новому генеральному плану. Дополнительные согласования прокола, не вытекающие из проекта и из индекса, отнесены к иным причинам. | L32: Средний | M32: 12000000 | N32: Часть трасс не согласована с балансодержателями. | O32: Б
A33: 03.03.02 | B33: Наружные сети теплоснабжения | C33: 90000000 | D33: 100000000 | E33: =D33-C33 | F33: =IF(AND(C33=0,D33=0),"—",IF(C33=0,"новая статья",E33/C33)) | G33: 7000000 | H33: 3000000 | I33: 0 | J33: =G33+H33+I33-E33 | K33: Индекс на исходную теплосеть. Небольшое увеличение диаметра по пересчету нагрузок. | L33: Низкий | M33: 0 | N33: Технические условия получены, трасса согласована. | O33: А
A34: 03.03.03 | B34: Наружное электроснабжение и трансформаторные подстанции | C34: 200000000 | D34: 270000000 | E34: =D34-C34 | F34: =IF(AND(C34=0,D34=0),"—",IF(C34=0,"новая статья",E34/C34)) | G34: 16000000 | H34: 35000000 | I34: 19000000 | J34: =G34+H34+I34-E34 | K34: Индекс тарифа на исходную мощность относительно дефлятора T0. Дополнительная мощность по новым ТЭП вместе с платой за присоединение этой мощности по действующему тарифу отнесена к изменениям ПСД. Удлинение трассы по требованию сетевой организации отнесено к иным причинам. | L34: Высокий | M34: 40000000 | N34: Договор технологического присоединения в редакции T1 не подписан. Тариф и трасса могут измениться до оплаты. | O34: Б
A35: 03.03.04 | B35: Наружные сети связи | C35: 40000000 | D35: 48000000 | E35: =D35-C35 | F35: =IF(AND(C35=0,D35=0),"—",IF(C35=0,"новая статья",E35/C35)) | G35: 3000000 | H35: 4000000 | I35: 1000000 | J35: =G35+H35+I35-E35 | K35: Индекс на исходные каналы. Дополнительные вводы под расширенный состав сетей связи. Разовая плата оператора сверх тарифа, заложенного дефлятором, отнесена к иным причинам. | L35: Низкий | M35: 2000000 | N35: Объем небольшой и технически определен. | O35: Б
A36: 03.03.05 | B36: Дороги, благоустройство и малые архитектурные формы | C36: 190000000 | D36: 232000000 | E36: =D36-C36 | F36: =IF(AND(C36=0,D36=0),"—",IF(C36=0,"новая статья",E36/C36)) | G36: 14000000 | H36: 16000000 | I36: 12000000 | J36: =G36+H36+I36-E36 | K36: Индекс покрытий и озеленения исходного генерального плана. Рост площади твердых покрытий и малых форм по новому решению. Перенос работ на следующий сезон и зимнее удорожание отнесены к иным причинам. | L36: Высокий | M36: 20000000 | N36: Проект благоустройства не заморожен. Работы стоят в конце графика и зависят от сезона. | O36: В
A37: 03.04 | B37: Технологическое оборудование и пусконаладка | C37: 0 | D37: 0 | E37: =D37-C37 | F37: =IF(AND(C37=0,D37=0),"—",IF(C37=0,"новая статья",E37/C37)) | G37: 0 | H37: 0 | I37: 0 | J37: =G37+H37+I37-E37 | K37: В условном периметре технологическое оборудование отсутствует. Строка сохраняется, чтобы классификатор не ломался на промышленном объекте. | L37: Низкий | M37: 0 | N37: Строка не используется. При появлении технологии риск оценивается отдельно. | O37: А
A38: 04 | B38: Затраты на управление проектом | C38: =SUM(C39,C40,C41) | D38: =SUM(D39,D40,D41) | E38: =D38-C38 | F38: =IF(AND(C38=0,D38=0),"—",IF(C38=0,"новая статья",E38/C38)) | G38: =SUM(G39,G40,G41) | H38: =SUM(H39,H40,H41) | I38: =SUM(I39,I40,I41) | J38: =G38+H38+I38-E38 | K38: Свертка вложенных строк. | L38: Высокий | M38: =SUM(M39,M40,M41) | N38: Оценка агрегата — наихудшая существенная вложенная строка.
A39: 04.01 | B39: Служба заказчика и технический заказчик | C39: 210000000 | D39: 270000000 | E39: =D39-C39 | F39: =IF(AND(C39=0,D39=0),"—",IF(C39=0,"новая статья",E39/C39)) | G39: 14000000 | H39: 10000000 | I39: 36000000 | J39: =G39+H39+I39-E39 | K39: Индексация оплаты труда исходной численности на исходный срок. Дополнительная численность под новые разделы фасадов и наружных сетей. Содержание исходной команды на месяцы сверх графика T0. | L39: Высокий | M39: 30000000 | N39: Срок ввода в модели T1 уже сдвинут. Следующий сдвиг увеличивает помесячные затраты почти линейно. Резерв на этот сдвиг в строке не заложен. | O39: А
A40: 04.02 | B40: Вознаграждение генподрядчика либо управляющего строительством | C40: 180000000 | D40: 210000000 | E40: =D40-C40 | F40: =IF(AND(C40=0,D40=0),"—",IF(C40=0,"новая статья",E40/C40)) | G40: 12000000 | H40: 12000000 | I40: 6000000 | J40: =G40+H40+I40-E40 | K40: Процент генподряда по исходной ставке на инфляционную и проектную части базы СМР. Изменение ставки и возмещаемые общеплощадочные затраты сверх процента отнесены к иным причинам. В модели без генподрядчика в строку ставится плата управляющему, а не пустое место без объяснения. | L40: Средний | M40: 8000000 | N40: Ставка процента зафиксирована. Возмещаемая часть при пролонгации остается открытой. | O40: А
A41: 04.03 | B41: Строительный контроль, охрана труда, качество и охрана площадки | C41: 90000000 | D41: 110000000 | E41: =D41-C41 | F41: =IF(AND(C41=0,D41=0),"—",IF(C41=0,"новая статья",E41/C41)) | G41: 4000000 | H41: 3000000 | I41: 13000000 | J41: =G41+H41+I41-E41 | K41: Индекс ставок строительного контроля на исходный срок. Расширение программы контроля под новые системы. Охрана и содержание надзора на месяцы пролонгации. | L41: Высокий | M41: 12000000 | N41: Затраты длятся до фактического ввода, а не до плановой даты T1. | O41: Б
...

Sheet Укрупненный анализ
A1: Укрупненный факторный анализ
A2: Отдельная таблица поверх постатейного анализа. Пять групп: СМР, ПИР, наружные сети и ТУ, коммерческие и административные затраты. Наружные сети вынесены из СМР. Проценты по кредиту не включены. Суммы — формулы со ссылкой на постатейные строки, без повторного ввода.
A4: Условный пример
A5: Группа | B5: Состав | C5: Базовый бюджет, руб. | D5: Откорректированный бюджет, руб. | E5: Отклонение, руб. | F5: Отклонение, % | G5: Фактор 1. Инфляция, руб. | H5: Фактор 2. Изменения ПСД, руб. | I5: Фактор 3. Иные причины, руб. | J5: Контроль, руб. | K5: Что входит в группу | L5: Риск до ввода | M5: Сумма риска, руб. | N5: Комментарий | O5: Класс надежности
A6: СМР | B6: Подготовка площадки, общестроительные работы, внутренние системы и технологическое оборудование. Коды 01, 03.01, 03.02, 03.04. | C6: =SUM('Условный пример'!C5,'Условный пример'!C17,'Условный пример'!C25,'Условный пример'!C37) | D6: =SUM('Условный пример'!D5,'Условный пример'!D17,'Условный пример'!D25,'Условный пример'!D37) | E6: =D6-C6 | F6: =IF(C6=0,"—",E6/C6) | G6: =SUM('Условный пример'!G5,'Условный пример'!G17,'Условный пример'!G25,'Условный пример'!G37) | H6: =SUM('Условный пример'!H5,'Условный пример'!H17,'Условный пример'!H25,'Условный пример'!H37) | I6: =SUM('Условный пример'!I5,'Условный пример'!I17,'Условный пример'!I25,'Условный пример'!I37) | J6: =G6+H6+I6-E6 | K6: Подготовка площадки, общестроительные работы, внутренние системы и технологическое оборудование. Коды 01, 03.01, 03.02, 03.04. | L6: =IF(OR('Условный пример'!L5="Высокий",'Условный пример'!L17="Высокий",'Условный пример'!L25="Высокий",'Условный пример'!L37="Высокий"),"Высокий",IF(OR('Условный пример'!L5="Средний",'Условный пример'!L17="Средний",'Условный пример'!L25="Средний",'Условный пример'!L37="Средний"),"Средний",IF(COUNTA('Условный пример'!L5,'Условный пример'!L17,'Условный пример'!L25,'Условный пример'!L37)=0,"","Низкий"))) | M6: =SUM('Условный пример'!M5,'Условный пример'!M17,'Условный пример'!M25,'Условный пример'!M37) | N6: Свертка постатейных строк. Сумма риска в тождество факторов не входит. | O6: свертка
A7: ПИР | B7: Изыскания, проект, рабочая документация, экспертиза и авторский надзор. Код 02. | C7: =SUM('Условный пример'!C10) | D7: =SUM('Условный пример'!D10) | E7: =D7-C7 | F7: =IF(C7=0,"—",E7/C7) | G7: =SUM('Условный пример'!G10) | H7: =SUM('Условный пример'!H10) | I7: =SUM('Условный пример'!I10) | J7: =G7+H7+I7-E7 | K7: Изыскания, проект, рабочая документация, экспертиза и авторский надзор. Код 02. | L7: =IF(OR('Условный пример'!L10="Высокий"),"Высокий",IF(OR('Условный пример'!L10="Средний"),"Средний",IF(COUNTA('Условный пример'!L10)=0,"","Низкий"))) | M7: =SUM('Условный пример'!M10) | N7: Свертка постатейных строк. Сумма риска в тождество факторов не входит. | O7: свертка
A8: Наружные сети и ТУ | B8: Наружные сети, технологическое присоединение и благоустройство. Код 03.03. | C8: =SUM('Условный пример'!C31) | D8: =SUM('Условный пример'!D31) | E8: =D8-C8 | F8: =IF(C8=0,"—",E8/C8) | G8: =SUM('Условный пример'!G31) | H8: =SUM('Условный пример'!H31) | I8: =SUM('Условный пример'!I31) | J8: =G8+H8+I8-E8 | K8: Наружные сети, технологическое присоединение и благоустройство. Код 03.03. | L8: =IF(OR('Условный пример'!L31="Высокий"),"Высокий",IF(OR('Условный пример'!L31="Средний"),"Средний",IF(COUNTA('Условный пример'!L31)=0,"","Низкий"))) | M8: =SUM('Условный пример'!M31) | N8: Свертка постатейных строк. Сумма риска в тождество факторов не входит. | O8: свертка
A9: Коммерческие | B9: Продвижение, офис продаж и брокерские комиссии. Код 05. | C9: =SUM('Условный пример'!C42) | D9: =SUM('Условный пример'!D42) | E9: =D9-C9 | F9: =IF(C9=0,"—",E9/C9) | G9: =SUM('Условный пример'!G42) | H9: =SUM('Условный пример'!H42) | I9: =SUM('Условный пример'!I42) | J9: =G9+H9+I9-E9 | K9: Продвижение, офис продаж и брокерские комиссии. Код 05. | L9: =IF(OR('Условный пример'!L42="Высокий"),"Высокий",IF(OR('Условный пример'!L42="Средний"),"Средний",IF(COUNTA('Условный пример'!L42)=0,"","Низкий"))) | M9: =SUM('Условный пример'!M42) | N9: Свертка постатейных строк. Сумма риска в тождество факторов не входит. | O9: свертка
A10: Административные | B10: Управление, страхование, резерв, гарантии и обязательные платежи. Коды 04 и 06. Проценты по кредиту не входят. | C10: =SUM('Условный пример'!C38,'Условный пример'!C46) | D10: =SUM('Условный пример'!D38,'Условный пример'!D46) | E10: =D10-C10 | F10: =IF(C10=0,"—",E10/C10) | G10: =SUM('Условный пример'!G38,'Условный пример'!G46) | H10: =SUM('Условный пример'!H38,'Условный пример'!H46) | I10: =SUM('Условный пример'!I38,'Условный пример'!I46) | J10: =G10+H10+I10-E10 | K10: Управление, страхование, резерв, гарантии и обязательные платежи. Коды 04 и 06. Проценты по кредиту не входят. | L10: =IF(OR('Условный пример'!L38="Высокий",'Условный пример'!L46="Высокий"),"Высокий",IF(OR('Условный пример'!L38="Средний",'Условный пример'!L46="Средний"),"Средний",IF(COUNTA('Условный пример'!L38,'Условный пример'!L46)=0,"","Низкий"))) | M10: =SUM('Условный пример'!M38,'Условный пример'!M46) | N10: Свертка постатейных строк. Сумма риска в тождество факторов не входит. | O10: свертка
A11: Итого | B11: Пять групп без повторного счета | C11: =SUM(C6:C10) | D11: =SUM(D6:D10) | E11: =SUM(E6:E10) | F11: =IF(C11=0,"—",E11/C11) | G11: =SUM(G6:G10) | H11: =SUM(H6:H10) | I11: =SUM(I6:I10) | J11: =SUM(J6:J10) | K11: Сумма групп равна постатейному итогу. | L11: =IF(OR('Условный пример'!L5="Высокий",'Условный пример'!L17="Высокий",'Условный пример'!L25="Высокий",'Условный пример'!L37="Высокий",'Условный пример'!L10="Высокий",'Условный пример'!L31="Высокий",'Условный пример'!L42="Высокий",'Условный пример'!L38="Высокий",'Условный пример'!L46="Высокий"),"Высокий",IF(OR('Условный пример'!L5="Средний",'Условный пример'!L17="Средний",'Условный пример'!L25="Средний",'Условный пример'!L37="Средний",'Условный пример'!L10="Средний",'Условный пример'!L31="Средний",'Условный пример'!L42="Средний",'Условный пример'!L38="Средний",'Условный пример'!L46="Средний"),"Средний",IF(COUNTA('Условный пример'!L5,'Условный пример'!L17,'Условный пример'!L25,'Условный пример'!L37,'Условный пример'!L10,'Условный пример'!L31,'Условный пример'!L42,'Условный пример'!L38,'Условный пример'!L46)=0,"","Низкий"))) | M11: =SUM(M6:M10) | N11: Проценты по кредиту в свод не входят.
A13: Рабочая таблица по листу «Шаблон»
A14: Группа | B14: Состав | C14: Базовый бюджет, руб. | D14: Откорректированный бюджет, руб. | E14: Отклонение, руб. | F14: Отклонение, % | G14: Фактор 1. Инфляция, руб. | H14: Фактор 2. Изменения ПСД, руб. | I14: Фактор 3. Иные причины, руб. | J14: Контроль, руб. | K14: Что входит в группу | L14: Риск до ввода | M14: Сумма риска, руб. | N14: Комментарий | O14: Класс надежности
A15: СМР | B15: Подготовка площадки, общестроительные работы, внутренние системы и технологическое оборудование. Коды 01, 03.01, 03.02, 03.04. | C15: =SUM('Шаблон'!C5,'Шаблон'!C17,'Шаблон'!C25,'Шаблон'!C37) | D15: =SUM('Шаблон'!D5,'Шаблон'!D17,'Шаблон'!D25,'Шаблон'!D37) | E15: =D15-C15 | F15: =IF(C15=0,"—",E15/C15) | G15: =SUM('Шаблон'!G5,'Шаблон'!G17,'Шаблон'!G25,'Шаблон'!G37) | H15: =SUM('Шаблон'!H5,'Шаблон'!H17,'Шаблон'!H25,'Шаблон'!H37) | I15: =SUM('Шаблон'!I5,'Шаблон'!I17,'Шаблон'!I25,'Шаблон'!I37) | J15: =G15+H15+I15-E15 | K15: Подготовка площадки, общестроительные работы, внутренние системы и технологическое оборудование. Коды 01, 03.01, 03.02, 03.04. | L15: =IF(OR('Шаблон'!L5="Высокий",'Шаблон'!L17="Высокий",'Шаблон'!L25="Высокий",'Шаблон'!L37="Высокий"),"Высокий",IF(OR('Шаблон'!L5="Средний",'Шаблон'!L17="Средний",'Шаблон'!L25="Средний",'Шаблон'!L37="Средний"),"Средний",IF(COUNTA('Шаблон'!L5,'Шаблон'!L17,'Шаблон'!L25,'Шаблон'!L37)=0,"","Низкий"))) | M15: =SUM('Шаблон'!M5,'Шаблон'!M17,'Шаблон'!M25,'Шаблон'!M37) | N15: Свертка постатейных строк. Сумма риска в тождество факторов не входит. | O15: свертка
A16: ПИР | B16: Изыскания, проект, рабочая документация, экспертиза и авторский надзор. Код 02. | C16: =SUM('Шаблон'!C10) | D16: =SUM('Шаблон'!D10) | E16: =D16-C16 | F16: =IF(C16=0,"—",E16/C16) | G16: =SUM('Шаблон'!G10) | H16: =SUM('Шаблон'!H10) | I16: =SUM('Шаблон'!I10) | J16: =G16+H16+I16-E16 | K16: Изыскания, проект, рабочая документация, экспертиза и авторский надзор. Код 02. | L16: =IF(OR('Шаблон'!L10="Высокий"),"Высокий",IF(OR('Шаблон'!L10="Средний"),"Средний",IF(COUNTA('Шаблон'!L10)=0,"","Низкий"))) | M16: =SUM('Шаблон'!M10) | N16: Свертка постатейных строк. Сумма риска в тождество факторов не входит. | O16: свертка
A17: Наружные сети и ТУ | B17: Наружные сети, технологическое присоединение и благоустройство. Код 03.03. | C17: =SUM('Шаблон'!C31) | D17: =SUM('Шаблон'!D31) | E17: =D17-C17 | F17: =IF(C17=0,"—",E17/C17) | G17: =SUM('Шаблон'!G31) | H17: =SUM('Шаблон'!H31) | I17: =SUM('Шаблон'!I31) | J17: =G17+H17+I17-E17 | K17: Наружные сети, технологическое присоединение и благоустройство. Код 03.03. | L17: =IF(OR('Шаблон'!L31="Высокий"),"Высокий",IF(OR('Шаблон'!L31="Средний"),"Средний",IF(COUNTA('Шаблон'!L31)=0,"","Низкий"))) | M17: =SUM('Шаблон'!M31) | N17: Свертка постатейных строк. Сумма риска в тождество факторов не входит. | O17: свертка
A18: Коммерческие | B18: Продвижение, офис продаж и брокерские комиссии. Код 05. | C18: =SUM('Шаблон'!C42) | D18: =SUM('Шаблон'!D42) | E18: =D18-C18 | F18: =IF(C18=0,"—",E18/C18) | G18: =SUM('Шаблон'!G42) | H18: =SUM('Шаблон'!H42) | I18: =SUM('Шаблон'!I42) | J18: =G18+H18+I18-E18 | K18: Продвижение, офис продаж и брокерские комиссии. Код 05. | L18: =IF(OR('Шаблон'!L42="Высокий"),"Высокий",IF(OR('Шаблон'!L42="Средний"),"Средний",IF(COUNTA('Шаблон'!L42)=0,"","Низкий"))) | M18: =SUM('Шаблон'!M42) | N18: Свертка постатейных строк. Сумма риска в тождество факторов не входит. | O18: свертка
A19: Административные | B19: Управление, страхование, резерв, гарантии и обязательные платежи. Коды 04 и 06. Проценты по кредиту не входят. | C19: =SUM('Шаблон'!C38,'Шаблон'!C46) | D19: =SUM('Шаблон'!D38,'Шаблон'!D46) | E19: =D19-C19 | F19: =IF(C19=0,"—",E19/C19) | G19: =SUM('Шаблон'!G38,'Шаблон'!G46) | H19: =SUM('Шаблон'!H38,'Шаблон'!H46) | I19: =SUM('Шаблон'!I38,'Шаблон'!I46) | J19: =G19+H19+I19-E19 | K19: Управление, страхование, резерв, гарантии и обязательные платежи. Коды 04 и 06. Проценты по кредиту не входят. | L19: =IF(OR('Шаблон'!L38="Высокий",'Шаблон'!L46="Высокий"),"Высокий",IF(OR('Шаблон'!L38="Средний",'Шаблон'!L46="Средний"),"Средний",IF(COUNTA('Шаблон'!L38,'Шаблон'!L46)=0,"","Низкий"))) | M19: =SUM('Шаблон'!M38,'Шаблон'!M46) | N19: Свертка постатейных строк. Сумма риска в тождество факторов не входит. | O19: свертка
A20: Итого | B20: Пять групп без повторного счета | C20: =SUM(C15:C19) | D20: =SUM(D15:D19) | E20: =SUM(E15:E19) | F20: =IF(C20=0,"—",E20/C20) | G20: =SUM(G15:G19) | H20: =SUM(H15:H19) | I20: =SUM(I15:I19) | J20: =SUM(J15:J19) | K20: Сумма групп равна постатейному итогу. | L20: =IF(OR('Шаблон'!L5="Высокий",'Шаблон'!L17="Высокий",'Шаблон'!L25="Высокий",'Шаблон'!L37="Высокий",'Шаблон'!L10="Высокий",'Шаблон'!L31="Высокий",'Шаблон'!L42="Высокий",'Шаблон'!L38="Высокий",'Шаблон'!L46="Высокий"),"Высокий",IF(OR('Шаблон'!L5="Средний",'Шаблон'!L17="Средний",'Шаблон'!L25="Средний",'Шаблон'!L37="Средний",'Шаблон'!L10="Средний",'Шаблон'!L31="Средний",'Шаблон'!L42="Средний",'Шаблон'!L38="Средний",'Шаблон'!L46="Средний"),"Средний",IF(COUNTA('Шаблон'!L5,'Шаблон'!L17,'Шаблон'!L25,'Шаблон'!L37,'Шаблон'!L10,'Шаблон'!L31,'Шаблон'!L42,'Шаблон'!L38,'Шаблон'!L46)=0,"","Низкий"))) | M20: =SUM(M15:M19) | N20: Проценты по кредиту в свод не входят.

Sheet Калькулятор позиции
A1: Калькулятор одной элементарной позиции
A2: F1 = v0 × p0 × (Iex − 1). F2 = v1 × pref − v0 × p0 × Iex. F3 = v1 × (p1 − pref). Если решение не изменилось, pref = p0 × Iex и вводится формулой. Если изменилось, pref — рыночная цена нового решения.
A4: Пример 1. Решение не изменилось: монолит, 10 000 м³ → 11 200 м³
A5: Исходный объем v0 | B5: 10000 | C5: м³
A6: Новый объем v1 | B6: 11200 | C6: м³
A7: Исходная цена p0 | B7: 18000 | C7: руб. за единицу
A8: Новая цена p1 | B8: 22500 | C8: руб. за единицу
A9: Коэффициент Iex | B9: =Индекс!B10 | C9: из листа «Индекс», пример 1
A10: Цена-ориентир pref | B10: =B7*B9 | C10: p0 × Iex, решение не менялось
A12: Базовый бюджет | B12: =B5*B7
A13: Откорректированный бюджет | B13: =B6*B8
A14: Отклонение | B14: =B13-B12
A15: Фактор 1. Инфляция | B15: =B5*B7*(B9-1)
A16: Фактор 2. Изменения ПСД | B16: =B6*B10-B5*B7*B9
A17: Фактор 3. Иные причины | B17: =B6*(B8-B10)
A18: Контроль | B18: =B15+B16+B17-B14
A19: Справочно: взаимодействие внутри фактора 2 | B19: =(B6-B5)*B7*(B9-1) | C19: В фактор 1 повторно не прибавляется
A21: Пример 2. Замена решения: кладка 5 000 м² заменена вентилируемым фасадом 5 300 м²
A22: Исходный объем v0 | B22: 5000
A23: Новый объем v1 | B23: 5300
A24: Исходная цена p0 | B24: 4500
A25: Новая цена p1 | B25: 9600
A26: Iex исходного решения | B26: 1.12
A27: Рыночная цена нового решения pref | B27: 9200
A29: Базовый бюджет | B29: =B22*B24
A30: Откорректированный бюджет | B30: =B23*B25
A31: Отклонение | B31: =B30-B29
A32: Фактор 1. Инфляция | B32: =B22*B24*(B26-1)
A33: Фактор 2. Изменения ПСД | B33: =B23*B27-B22*B24*B26
A34: Фактор 3. Иные причины | B34: =B23*(B25-B27)
A35: Контроль | B35: =B32+B33+B34-B31
A37: Инфляция в примере 2 относится только к снятой кладке. Стоимость нового фасада в фактор 1 не входит.

Sheet Ориентировочный бюджет
A1: Ориентировочный бюджет до рабочей документации
A2: Исходного сметного объема нет. Инфляция считается на удельную ставку паспорта. К изменениям проекта относятся площадь и замена названного решения. Первый обсчет той же программы раскрывается внутри иных причин как F3d и вторым фактором не становится.
A4: Паспорт и инфляция
A5: Исходный измеритель Q0 | B5: 50000 | C5: м² общей площади, как в модели T0
A6: Удельная ставка a0 | B6: 120000 | C6: руб. без НДС за единицу измерителя
A7: Коэффициент Iex | B7: 1.25 | C7: дефлятор паспорта, не веса новой сметы
A8: Базовый бюджет B0 | B8: =B5*B6 | C8: a0 × Q0
A9: Фактор 1. Инфляция | B9: =B8*(B7-1) | C9: только на сумму паспорта
A10: Проиндексированный паспорт | B10: =B8*B7 | C10: B0 × Iex
A12: Отступление от паспорта
A13: Измеритель T1, Q1 | B13: 52000 | C13: новый ТЭП той же единицы измерения
A14: Стоимость той же программы S | B14: 7750000000 | C14: рабочая документация и цены T1 без лишней площади и без замененного решения
A15: Удельная стоимость той же программы | B15: =IF(B5=0,"",B14/B5) | C15: S / Q0, руб. за единицу
A16: Фактор 2 по измерителю | B16: =(B13-B5)*B15 | C16: приростная площадь в текущей полноте исходного стандарта
A17: Стоимость нового решения на Q0 | B17: 1400000000 | C17: замена решения, названного в паспорте
A18: Доля замененного решения в ставке T0 | B18: 800000000 | C18: Allowance0 из паспорта или аналога
A19: U, чистая замена | B19: =B17-B18*B7 | C19: Cost1 − Allowance0 × Iex
A20: Фактор 2. Изменения ПСД | B20: =B16+B19 | C20: площадь и замена; детализация сюда не входит
A22: Факт, уточнение и прочие иные причины
A23: Откорректированный бюджет B1 | B23: 8560000000 | C23: статья T1, тот же периметр
A24: Фактор 3. Иные причины | B24: =B23-B8-B9-B20 | C24: остаток после инфляции и отступлений от паспорта
A25: В том числе F3d, уточнение по РД | B25: =B14-B10 | C25: S − проиндексированный паспорт; это не изменение проекта
A26: В том числе прочие иные причины | B26: =B24-B25 | C26: срок, закупка, форс-мажор и налог
A27: Отклонение | B27: =B23-B8
A28: Контроль тождества | B28: =B9+B20+B24-B27 | C28: F1 + F2 + F3 − отклонение, должно быть 0
A29: Контроль состава B1 | B29: =B14+B20+B26-B23 | C29: S + F2 + прочие иные − B1, должно быть 0
A31: Числа листа — учебный пример раздела 5.10: 6,00 млрд руб. становятся 8,56 млрд руб. Из отклонения 2,56 млрд руб. инфляция паспорта составляет 1,50 млрд, изменения площади и фасада — 0,71 млрд, уточнение по рабочей документации — 0,25 млрд, прочие иные причины — 0,10 млрд.

Sheet Индекс
A1: Сборка коэффициента инфляции Iex
A2: Iex = сумма весов × индексов групп. Сумма весов обязана быть равна 1. Накладные расходы и прибыль процентом отдельным индексом не умножаются: они пересчитываются от проиндексированных прямых затрат по старым ставкам. Берется отношение индекса квартала T1 к индексу квартала T0, а не абсолютный индекс к базе 2001 года.
A4: Ресурсная группа | B4: Вес в цене T0 | C4: Индекс группы Iex | D4: Вклад в Iex
A5: Материалы | B5: 0.62 | C5: 1.19 | D5: =B5*C5
A6: Машины и механизмы | B6: 0.11 | C6: 1.14 | D6: =B6*C6
A7: Оплата труда | B7: 0.27 | C7: 1.16 | D7: =B7*C7
A8: Перевозка, если выделена отдельно | B8: 0 | C8: 1 | D8: =B8*C8
A9: Сумма весов | B9: =SUM(B5:B8) | C9: Должна быть равна 100%
A10: Iex позиции | B10: =IF(ABS(B9-1)>0.000001,"проверьте веса",SUM(D5:D8)) | C10: Этот коэффициент подставлен в пример 1 калькулятора позиции
A12: Если бюджет T0 уже содержал прогнозный дефлятор, в колонку индекса ставится отношение фактического или нового прогнозного индекса к исходному прогнозу, а не полный рост от даты T0.

Sheet Производные затраты
A1: Процент генподряда и содержание команды
A2: Эти статьи считаются после разложения базы. Процент не индексируется вторым кругом. Проценты по кредиту в бюджет проекта не входят и на этом листе не считаются.
A4: Вознаграждение: процент от базы плюс помесячное содержание
A5: База T0, руб. | B5: 3100000000
A6: Фактор 1 базы, руб. | B6: 280000000
A7: Фактор 2 базы, руб. | B7: 190000000
A8: Фактор 3 базы, руб. | B8: 30000000
A9: Ставка процента T0 | B9: 0.03
A10: Ставка процента T1 | B10: 0.031
A11: Исходная численность, чел. | B11: 12
A12: Дополнительная численность из-за ПСД, чел. | B12: 2
A13: Исходный срок, мес. | B13: 36
A14: Срок T1, мес. | B14: 43
A15: Стоимость человека в месяц T0, руб. | B15: 350000
A16: Iex оплаты труда | B16: 1.12
A17: Фактическая стоимость человека в месяц T1, руб. | B17: 410000
A19: База T1 | B19: =B5+B6+B7+B8
A20: Вознаграждение T0 | B20: =B9*B5+B11*B13*B15
A21: Вознаграждение T1 | B21: =B10*B19+(B11+B12)*B14*B17
A22: Отклонение | B22: =B21-B20
A23: Фактор 1 | B23: =B9*B6+B11*B13*B15*(B16-1)
A24: Фактор 2 | B24: =B9*B7+B12*B13*B15*B16
A25: Фактор 3 | B25: =B22-B23-B24
A26: Контроль | B26: =B23+B24+B25-B22
A28: Проценты по кредиту в расчет не включаются: бюджеты проектов эти затраты не содержат.

Sheet Риск
A1: Оценка риска дальнейшего роста бюджета до ввода
A2: Шкала оценивает новое отклонение сверх откорректированного бюджета. Она не переразлагает уже учтенные факторы.
A4: Признак | B4: 0 баллов | C4: 1 балл | D4: 2 балла | E4: Балл строки
A5: Доля строки без подписанного договора | B5: менее 15% | C5: от 15% до 40% | D5: более 40% | E5: 0
A6: Тип цены подписанного объема | B6: твердая цена без эскалации | C6: единичные расценки | D6: открытая цена или договор не подписан | E6: 0
A7: Зрелость рабочей документации | B7: заморожена не менее чем на 90% | C7: от 60% до 90% | D7: менее 60% | E7: 0
A8: Резерв против ожидаемой стоимости названных рисков | B8: резерв покрывает не менее 100% | C8: покрытие от 50% до 100% | D8: покрытие менее 50% | E8: 0
A9: Срок | B9: есть резерв времени | C9: резерв выбран или задержка меньше 3 месяцев | D9: задержка от 3 месяцев или вероятна претензия на срок | E9: 0
A10: Несогласованные изменения и претензии | B10: менее 1% строки | C10: от 1% до 3% | D10: более 3% | E10: 0
A11: Сумма баллов | E11: =SUM(E5:E10)
A12: Принудительное повышение: нет ТУ, отрицательная экспертиза, обременение или неизвестная плата за присоединение | E12: 0
A13: Оценка | E13: =IF(E12>=2,"Высокий",IF(AND(E12=1,E11<=3),"Средний",IF(E11<=3,"Низкий",IF(E11<=7,"Средний","Высокий"))))
A15: 0–3 балла — низкий риск, 4–7 — средний, 8–12 — высокий. Одно блокирующее обстоятельство поднимает оценку не ниже средней, два — до высокой. Величина возможного удорожания в рублях вносится в колонку «Сумма риска» постатейной таблицы и в тождество факторов не входит.

Sheet Реестр документов
A1: Минимальный реестр документов для анализа увеличения бюджета
A2: В запросе заказчику только документы, без которых фактор нельзя подтвердить. Объяснительная записка документ не заменяет. Проценты по кредиту не запрашиваются: в бюджет проекта они не входят.
A4: Группа | B4: Документ | C4: Какой фактор закрывает | D4: Что сверяется | E4: Если документа нет
A5: Сквозные | B5: Протокол утверждения базового бюджета, модель и макродопущения T0 | C5: Все | D5: Какой файл является базой и какие дефляторы утверждены | E5: База не идентифицирована, расчет не начинается
A6: Сквозные | B6: Файл откорректированного бюджета T1 и пояснения застройщика | C6: Все | D6: От какой версии отстраивается анализ | E6: Нет предмета анализа
A7: Сквозные | B7: Письма Минстроя, выгрузка ФГИС ЦС или публикация Росстата | C7: F1 | D7: Отношение индексов, а не индекс к базе 2001 года | E7: Называть сумму инфляцией нельзя
A8: Сквозные | B8: Графики T0 и T1 и справка о причинах сдвига | C8: F3 против F1 | D8: Какие месяцы относятся к сроку, а не к индексу | E8: Сдвиг сроков остается неразделенным
A9: Сквозные | B9: Справка о периметре: очереди, выбытия, затраты вне бюджета | C9: До факторов | D9: Сопоставимость итогов | E9: Факторы могут объяснять чужой объект
A10: Сквозные | B10: Регистр фактических затрат на дату T1 против бюджета | C10: Все | D10: Бюджет T1 связан с фактом | E10: Бюджет T1 может быть декларацией
A11: Ориентировочный бюджет | B11: Модель T0: удельная ставка, состав, дата цен, дефлятор, ТЭП и задание | C11: F1, F2 | D11: Паспорт программы, от которого считаются инфляция и отступление | E11: Инфляцию и изменение проекта не от чего считать
A12: Ориентировочный бюджет | B12: Перечень исключений из ставки и резерв на недопроектированность | C12: F3d | D12: Что ставка не обещала | E12: Уточнение смешивается с пропуском периметра
A13: Ориентировочный бюджет | B13: Рабочая документация и сметы T1 и таблица отступлений, исключенных из стоимости той же программы | C13: S и F3d | D13: Стоимость той же программы в ценах T1 | E13: F3d не доказано
A14: СМР | B14: Договоры, дополнительные соглашения и ведомости расценок обеих дат | C14: F1, F3 | D14: Исходная и новая цена, формула эскалации | E14: Нет подтверждения цены
A15: СМР | B15: Калькуляция существенных расценок или веса материалов, машин и оплаты труда | C15: F1 | D15: Из чего собран индекс статьи | E15: Индекс становится среднеотраслевым, класс не выше Б
... A29: Финансы | B29: Договоры гарантий и расчет обязательных платежей периода строительства | C29: F3 | D29: Пролонгация и новые платежи | E29: Строка комиссий не раскрыта

Sheet Контроль
A1: Контроль условного примера
A2: Все значения подтянуты формулами с листа «Условный пример». Нулевой контроль — условие выпуска таблицы.
A4: Проверка | B4: Значение | C4: Ожидание | D4: Сошлось
A5: Базовый бюджет, руб. | B5: ='Условный пример'!C50 | C5: 7020000000 | D5: =ABS(B5-C5)<0.001
A6: Откорректированный бюджет, руб. | B6: ='Условный пример'!D50 | C6: 8175000000 | D6: =ABS(B6-C6)<0.001
A7: Отклонение, руб. | B7: ='Условный пример'!E50 | C7: 1155000000 | D7: =ABS(B7-C7)<0.001
A8: Фактор 1, руб. | B8: ='Условный пример'!G50 | C8: 535000000 | D8: =ABS(B8-C8)<0.001
A9: Фактор 2, руб. | B9: ='Условный пример'!H50 | C9: 446000000 | D9: =ABS(B9-C9)<0.001
A10: Фактор 3, руб. | B10: ='Условный пример'!I50 | C10: 174000000 | D10: =ABS(B10-C10)<0.001
A11: Контроль тождества, руб. | B11: ='Условный пример'!J50 | C11: 0 | D11: =ABS(B11-C11)<0.001
A12: Отклонение к базе | B12: =B7/B5 | C12: 0.16452991 | D12: =ABS(B12-C12)<0.001
A13: Доля инфляции в приросте | B13: =B8/B7 | C13: 0.46320346 | D13: =ABS(B13-C13)<0.001
A14: Доля ПСД в приросте | B14: =B9/B7 | C14: 0.38614719 | D14: =ABS(B14-C14)<0.001
A15: Доля иных причин в приросте | B15: =B10/B7 | C15: 0.15064935 | D15: =ABS(B15-C15)<0.001
A16: Сумма риска, руб. | B16: ='Условный пример'!M50 | C16: 444000000 | D16: =ABS(B16-C16)<0.001
A17: Контроль упрощенной суммы фактора 3, руб. | B17: ='Условный пример'!C58 | C17: 0 | D17: =ABS(B17-C17)<0.001
A18: Укрупненный итог, базовый бюджет, руб. | B18: ='Укрупненный анализ'!C11 | C18: 7020000000 | D18: =ABS(B18-C18)<0.001
A19: Укрупненный итог, контроль, руб. | B19: ='Укрупненный анализ'!J11 | C19: 0 | D19: =ABS(B19-C19)<0.001
A20: Укрупненный итог, сумма риска, руб. | B20: ='Укрупненный анализ'!M11 | C20: 444000000 | D20: =ABS(B20-C20)<0.001
A22: Позиция монолита, контроль калькулятора, руб. | B22: ='Калькулятор позиции'!B18
A23: Замена фасада, контроль калькулятора, руб. | B23: ='Калькулятор позиции'!B35
A24: Контроль производного вознаграждения, руб. | B24: ='Производные затраты'!B26
A25: Контроль ориентировочного бюджета, руб. | B25: ='Ориентировочный бюджет'!B28
A26: Контроль состава ориентировочного бюджета, руб. | B26: ='Ориентировочный бюджет'!B29
